<?xml version="1.0"?>
<robot name="hek">

  <link name="world"/>

  <link name="base">
    <visual>
      <origin xyz="-0.05 -0.14 0" rpy="1.57 0 1.57"/>
      <geometry>
        <mesh filename="package://cs2r_desc/stl/base0.STL"
              scale="0.001 0.001 0.001"
        />
      </geometry>
      <material name="white">
        <color rgba="1 1 1 1"/>
      </material>
    </visual>
  </link>

  <joint name="fixed" type="fixed">
    <parent link="world"/>
    <child link="base"/>
  </joint>

  <link name="abd_z_joint">
    <visual>
      <origin xyz="-0.024 0.0231 0" rpy="1.57 0 0"/>
      <geometry>
        <mesh filename="package://cs2r_desc/stl/abd_z_joint0.STL"
              scale="0.001 0.001 0.001"
        />
      </geometry>
      <material name="white"/>
    </visual>
  </link>

  <joint name="abd_z" type="revolute">
    <origin xyz="0 0 0.049" rpy="0 0 0"/>
    <parent link="base"/>
    <child link="abd_z_joint"/>
    <axis xyz="0 0 1"/>
    <limit effort="100" velocity="1.0" lower="-0.75" upper="0.75" />
  </joint>

  <link name="abd">
    <visual>
      <origin xyz="-0.0285 0.0285 -0.015" rpy="1.57 0 0"/>
      <geometry>
        <mesh filename="package://cs2r_desc/stl/abd.STL"
              scale="0.001 0.001 0.001"
        />
      </geometry>
      <material name="black">
        <color rgba="0 0 0 1"/>
      </material>
    </visual>
  </link>

  <joint name="abd_x" type="revolute">
    <origin xyz="0 0 0.0531" rpy="0 0 1.57"/>
    <parent link="abd_z_joint"/>
    <child link="abd"/>
    <axis xyz="0 1 0"/>
    <limit effort="100" velocity="1.0" lower="-0.5" upper="0.5" />
  </joint>


  <link name="chest">
    <visual>
      <origin xyz="0.05 0.149895 -0.014" rpy="1.57 0 -1.57"/>
      <geometry>
        <mesh filename="package://cs2r_desc/stl/chest0.STL"
              scale="0.001 0.001 0.001"
        />
      </geometry>
      <material name="white"/>
    </visual>
  </link>

  <joint name="abd_y" type="revolute">
    <origin xyz="0 0 0.05" rpy="0 0 -1.57"/>
    <parent link="abd"/>
    <child link="chest"/>
    <axis xyz="0 1 0"/>
    <limit effort="100" velocity="1.0" lower="-0.7" upper="1.0" />
  </joint>


  <link name="neck">
    <visual>
      <origin xyz="-0.015 -0.0255 0" rpy="1.57 0 1.57"/>
      <geometry>
        <mesh filename="package://cs2r_desc/stl/neck.STL"
              scale="0.001 0.001 0.001"
        />
      </geometry>
      <material name="black"/>
    </visual>
  </link>

  <joint name="neck_z" type="revolute">
    <origin xyz="0 0 0.17654" rpy="0 0 0"/>
    <parent link="chest"/>
    <child link="neck"/>
    <axis xyz="0 0 1"/>
    <limit effort="100" velocity="1.0" lower="-1.0" upper="1.0" />
  </joint>


  <link name="head">
    <visual>
      <origin xyz="0.0535 0.08 -0.0115" rpy="1.57 0 -1.57"/>
      <geometry>
        <mesh filename="package://cs2r_desc/stl/head.STL"
              scale="0.001 0.001 0.001"
        />
      </geometry>
      <material name="white"/>
    </visual>
  </link>

  <joint name="neck_y" type="revolute">
    <origin xyz="0 0 0.02" rpy="0 0 0"/>
    <parent link="neck"/>
    <child link="head"/>
    <axis xyz="0 1 0"/>
    <limit effort="100" velocity="1.0" lower="-0.6" upper="0.7" />
  </joint>

  <!-- LEFT ARM *****************************************************************-->

  <link name="l_shoulder">
    <visual>
      <origin xyz="0 0 0" rpy="0 0 0"/>
      <geometry>
        <mesh filename="package://cs2r_desc/stl/shoulder.STL"
              scale="0.001 0.001 0.001"
        />
      </geometry>
      <material name="white"/>
    </visual>
  </link>

  <joint name="l_shoulder_y" type="revolute">
    <origin xyz="0.001 0.14819 0.1286" rpy="0 0 1.57"/>
    <parent link="chest"/>
    <child link="l_shoulder"/>
    <axis xyz="-1 0 0"/>
    <limit effort="100" velocity="1.0" lower="-1.0" upper="2.7" />
  </joint>

  <link name="l_upper_arm_up">
    <visual>
      <origin xyz="-0.0258 0.02385 -0.0416" rpy="1.57 0 0"/>
      <geometry>
        <mesh filename="package://cs2r_desc/stl/l_upper_arm_up.STL"
              scale="0.001 0.001 0.001"
        />
      </geometry>
      <material name="white"/>
    </visual>
  </link>

  <joint name="l_shoulder_x" type="revolute">
    <origin xyz="0.035 0 0" rpy="0 0 0"/>
    <parent link="l_shoulder"/>
    <child link="l_upper_arm_up"/>
    <axis xyz="0 -1 0"/>
    <limit effort="100" velocity="1.0" lower="0" upper="1.7" />
  </joint>

  <link name="l_upper_arm">
    <visual>
      <origin xyz="0 0 0" rpy="0 0 0"/>
      <geometry>
        <mesh filename="package://cs2r_desc/stl/upper_arm.STL"
              scale="0.001 0.001 0.001"
        />
      </geometry>
      <material name="white"/>
    </visual>
  </link>

  <joint name="l_shoulder_z" type="revolute">
    <origin xyz="0 0.01 -0.0416" rpy="0 0 -1.57"/>
    <parent link="l_upper_arm_up"/>
    <child link="l_upper_arm"/>
    <axis xyz="0 0 1"/>
    <limit effort="100" velocity="1.0" lower="-1.57" upper="1.57" />
  </joint>

  <link name="l_elpow">
    <visual>
      <origin xyz="0 0 0" rpy="0 0 0"/>
      <geometry>
        <mesh filename="package://cs2r_desc/stl/elpow.STL"
              scale="0.001 0.001 0.001"
        />
      </geometry>
      <material name="black"/>
    </visual>
  </link>

  <joint name="l_elpow_y" type="revolute">
    <origin xyz="0.01 -0.001 -0.1557" rpy="0 0 0"/>
    <parent link="l_upper_arm"/>
    <child link="l_elpow"/>
    <axis xyz="0 -1 0"/>
    <limit effort="100" velocity="1.0" lower="0.35" upper="2.5" />
  </joint>

  <link name="l_forearm">
    <visual>
      <origin xyz="0 0 0" rpy="0 0 0"/>
      <geometry>
        <mesh filename="package://cs2r_desc/stl/l_forearm.STL"
              scale="0.001 0.001 0.001"
        />
      </geometry>
      <material name="white"/>
    </visual>
  </link>

  <joint name="l_elpow_x" type="revolute">
    <origin xyz="-0.02078 0.0 -0.03755" rpy="0 1.57 0"/>
    <parent link="l_elpow"/>
    <child link="l_forearm"/>
    <axis xyz="-1 0 0"/>
    <limit effort="100" velocity="1.0" lower="0.0" upper="3.14" />
  </joint>

  <link name="l_wrist">
    <visual>
      <origin xyz="0 0 0" rpy="0 0 0"/>
      <geometry>
        <mesh filename="package://cs2r_desc/stl/wrist.STL"
              scale="0.001 0.001 0.001"
        />
      </geometry>
      <material name="white"/>
    </visual>
  </link>

  <joint name="l_wrist_y" type="revolute">
    <origin xyz="0.17325 0.0015 0" rpy="0 0 0"/>
    <parent link="l_forearm"/>
    <child link="l_wrist"/>
    <axis xyz="0 1 0"/>
    <limit effort="100" velocity="1.0" lower="-1.0" upper="1.0" />
  </joint>

  <!--left_hand-->

  <link name="l_palm">
    <visual>
      <origin xyz="0 0 0" rpy="0 0 0"/>
      <geometry>
        <mesh filename="package://cs2r_desc/stl/l_palm.STL"
              scale="0.001 0.001 0.001"
        />
      </geometry>
      <material name="white"/>
    </visual>
  </link>

  <joint name="l_wrist_z" type="revolute">
    <origin xyz="0 0 0" rpy="0 0 0"/>
    <parent link="l_wrist"/>
    <child link="l_palm"/>
    <axis xyz="0 0 1"/>
    <limit effort="100" velocity="1.0" lower="-0.65" upper="0.65" />
  </joint>

  <link name="l_thumb_joint">
    <visual>
      <origin xyz="0 0 0" rpy="0 0 0"/>
      <geometry>
        <mesh filename="package://cs2r_desc/stl/l_thumb_joint.STL"
              scale="0.001 0.001 0.001"
        />
      </geometry>
      <material name="white"/>
    </visual>
  </link>

  <joint name="l_thumb_joint_x" type="revolute">
    <origin xyz="0.0417 -0.0291 -0.0057" rpy="0 0 0"/>
    <parent link="l_palm"/>
    <child link="l_thumb_joint"/>
    <axis xyz="1 0 0"/>
    <limit effort="100" velocity="1.0" lower="0.1" upper="2" />
  </joint>

  <link name="l_thumb1">
    <visual>
      <origin xyz="0 0 0" rpy="0 0 0"/>
      <geometry>
        <mesh filename="package://cs2r_desc/stl/Thumb1.STL"
              scale="0.001 0.001 0.001"
        />
      </geometry>
      <material name="white"/>
    </visual>
  </link>

  <joint name="l_thumb" type="revolute">
    <origin xyz="0.0068 -0.019 0" rpy="0.3 -0.0 -1.06"/>
    <parent link="l_thumb_joint"/>
    <child link="l_thumb1"/>
    <axis xyz="0 1 0"/>
    <limit effort="100" velocity="1.0" lower="0" upper="1.4" />
  </joint>

  <link name="l_thumb2">
    <visual>
      <origin xyz="0 0 0" rpy="0 0 0"/>
      <geometry>
        <mesh filename="package://cs2r_desc/stl/Thumb2.STL"
              scale="0.001 0.001 0.001"
        />
      </geometry>
      <material name="white"/>
    </visual>
  </link>

  <joint name="l_thumb1_2" type="revolute">
    <origin xyz="0.021 0 0" rpy="0 0 0"/>
    <parent link="l_thumb1"/>
    <child link="l_thumb2"/>
    <axis xyz="0 1 0"/>
    <mimic joint="l_thumb" multiplier="1"/>
    <limit effort="100" velocity="1.0" lower="0" upper="1.4" />
  </joint>

  <link name="l_index_finger_joint">
    <visual>
      <origin xyz="0 0 0" rpy="0 0 0"/>
      <geometry>
        <mesh filename="package://cs2r_desc/stl/finger_joint.STL"
              scale="0.001 0.001 0.001"
        />
      </geometry>
      <material name="white"/>
    </visual>
  </link>

  <joint name="l_fingers_z" type="revolute">
    <origin xyz="0.06512 -0.0225 0.0051" rpy="0 0 0"/>
    <parent link="l_palm"/>
    <child link="l_index_finger_joint"/>
    <axis xyz="0 0 1"/>
    <limit effort="100" velocity="1.0" lower="-0.25" upper="0.15" />
  </joint>

  <link name="l_index1">
    <visual>
      <origin xyz="0 0 0" rpy="0 0 0"/>
      <geometry>
        <mesh filename="package://cs2r_desc/stl/Index1.STL"
              scale="0.001 0.001 0.001"
        />
      </geometry>
      <material name="white"/>
    </visual>
  </link>

  <joint name="l_index" type="revolute">
    <origin xyz="0.0115 0 -0.0005" rpy="0 0 0"/>
    <parent link="l_index_finger_joint"/>
    <child link="l_index1"/>
    <axis xyz="0 1 0"/>
    <limit effort="100" velocity="1.0" lower="0.0" upper="1.5" />
  </joint>

  <link name="l_index2">
    <visual>
      <origin xyz="0 0 0" rpy="0 0 0"/>
      <geometry>
        <mesh filename="package://cs2r_desc/stl/Index2.STL"
              scale="0.001 0.001 0.001"
        />
      </geometry>
      <material name="white"/>
    </visual>
  </link>

  <joint name="l_index1_2" type="revolute">
    <origin xyz="0.022 0 0" rpy="0 0 0"/>
    <parent link="l_index1"/>
    <child link="l_index2"/>
    <axis xyz="0 1 0"/>
    <mimic joint="l_index" multiplier="1"/>
    <limit effort="100" velocity="1.0" lower="0.0" upper="1.5" />
  </joint>

  <link name="l_index3">
    <visual>
      <origin xyz="0 0 0" rpy="0 0 0"/>
      <geometry>
        <mesh filename="package://cs2r_desc/stl/Index3.STL"
              scale="0.001 0.001 0.001"
        />
      </geometry>
      <material name="white"/>
    </visual>
  </link>

  <joint name="l_index2_3" type="revolute">
    <origin xyz="0.0146 0 0" rpy="0 0 0"/>
    <parent link="l_index2"/>
    <child link="l_index3"/>
    <axis xyz="0 1 0"/>
    <mimic joint="l_index" multiplier="1"/>
    <limit effort="100" velocity="1.0" lower="0.0" upper="1.5" />
  </joint>

  <link name="l_middle_finger_joint">
    <visual>
      <origin xyz="0 0 0" rpy="0 0 0"/>
      <geometry>
        <mesh filename="package://cs2r_desc/stl/finger_joint.STL"
              scale="0.001 0.001 0.001"
        />
      </geometry>
      <material name="white"/>
    </visual>
  </link>

  <joint name="l_midlle_z" type="fixed">
    <origin xyz="0.0665 -0.00733 0.0051" rpy="0 0 0"/>
    <parent link="l_palm"/>
    <child link="l_middle_finger_joint"/>
  </joint>

  <link name="l_middle1">
    <visual>
      <origin xyz="0 0 0" rpy="0 0 0"/>
      <geometry>
        <mesh filename="package://cs2r_desc/stl/Majeure1.STL"
              scale="0.001 0.001 0.001"
        />
      </geometry>
      <material name="white"/>
    </visual>
  </link>

  <joint name="l_middle" type="revolute">
    <origin xyz="0.0115 0 -0.0005" rpy="0 0 0"/>
    <parent link="l_middle_finger_joint"/>
    <child link="l_middle1"/>
    <axis xyz="0 1 0"/>
    <limit effort="100" velocity="1.0" lower="0.0" upper="1.5" />
  </joint>

  <link name="l_middle2">
    <visual>
      <origin xyz="0 0 0" rpy="0 0 0"/>
      <geometry>
        <mesh filename="package://cs2r_desc/stl/Majeure2.STL"
              scale="0.001 0.001 0.001"
        />
      </geometry>
      <material name="white"/>
    </visual>
  </link>

  <joint name="l_middle1_2" type="revolute">
    <origin xyz="0.023 0 0" rpy="0 0 0"/>
    <parent link="l_middle1"/>
    <child link="l_middle2"/>
    <axis xyz="0 1 0"/>
    <mimic joint="l_middle" multiplier="1"/>
    <limit effort="100" velocity="1.0" lower="0.0" upper="1.5" />
  </joint>

  <link name="l_middle3">
    <visual>
      <origin xyz="0 0 0" rpy="0 0 0"/>
      <geometry>
        <mesh filename="package://cs2r_desc/stl/Majeure3.STL"
              scale="0.001 0.001 0.001"
        />
      </geometry>
      <material name="white"/>
    </visual>
  </link>

  <joint name="l_middle2_3" type="revolute">
    <origin xyz="0.0155 0 0" rpy="0 0 0"/>
    <parent link="l_middle2"/>
    <child link="l_middle3"/>
    <axis xyz="0 1 0"/>
    <mimic joint="l_middle" multiplier="1"/>
    <limit effort="100" velocity="1.0" lower="0.0" upper="1.5" />
  </joint>

  <link name="l_ring_finger_joint">
    <visual>
      <origin xyz="0 0 0" rpy="0 0 0"/>
      <geometry>
        <mesh filename="package://cs2r_desc/stl/finger_joint.STL"
              scale="0.001 0.001 0.001"
        />
      </geometry>
      <material name="white"/>
    </visual>
  </link>

  <joint name="l_ring_z" type="revolute">
    <origin xyz="0.064 0.00747 0.0051" rpy="0 0 0"/>
    <parent link="l_palm"/>
    <child link="l_ring_finger_joint"/>
    <axis xyz="0 0 1"/>
    <mimic joint="l_fingers_z" multiplier="-1"/>
    <limit effort="100" velocity="1.0" lower="-0.4" upper="0.2" />
  </joint>

  <link name="l_ring1">
    <visual>
      <origin xyz="0 0 0" rpy="0 0 0"/>
      <geometry>
        <mesh filename="package://cs2r_desc/stl/RingFinger1.STL"
              scale="0.001 0.001 0.001"
        />
      </geometry>
      <material name="white"/>
    </visual>
  </link>

  <joint name="l_ring" type="revolute">
    <origin xyz="0.0115 0 -0.0005" rpy="0 0 0"/>
    <parent link="l_ring_finger_joint"/>
    <child link="l_ring1"/>
    <axis xyz="0 1 0"/>
    <limit effort="100" velocity="1.0" lower="0.0" upper="1.5" />
  </joint>

  <link name="l_ring2">
    <visual>
      <origin xyz="0 0 0" rpy="0 0 0"/>
      <geometry>
        <mesh filename="package://cs2r_desc/stl/RingFinger2.STL"
              scale="0.001 0.001 0.001"
        />
      </geometry>
      <material name="white"/>
    </visual>
  </link>

  <joint name="l_ring1_2" type="revolute">
    <origin xyz="0.021 0 0" rpy="0 0 0"/>
    <parent link="l_ring1"/>
    <child link="l_ring2"/>
    <axis xyz="0 1 0"/>
    <mimic joint="l_ring" multiplier="1"/>
    <limit effort="100" velocity="1.0" lower="0.0" upper="1.5" />
  </joint>

  <link name="l_ring3">
    <visual>
      <origin xyz="0 0 0" rpy="0 0 0"/>
      <geometry>
        <mesh filename="package://cs2r_desc/stl/RingFinger3.STL"
              scale="0.001 0.001 0.001"
        />
      </geometry>
      <material name="white"/>
    </visual>
  </link>

  <joint name="l_ring2_3" type="revolute">
    <origin xyz="0.014 0 0" rpy="0 0 0"/>
    <parent link="l_ring2"/>
    <child link="l_ring3"/>
    <axis xyz="0 1 0"/>
    <mimic joint="l_ring" multiplier="1"/>
    <limit effort="100" velocity="1.0" lower="0.0" upper="1.5" />
  </joint>

  <link name="l_auri_finger_joint">
    <visual>
      <origin xyz="0 0 0" rpy="0 0 0"/>
      <geometry>
        <mesh filename="package://cs2r_desc/stl/finger_joint.STL"
              scale="0.001 0.001 0.001"
        />
      </geometry>
      <material name="white"/>
    </visual>
  </link>

  <joint name="l_auri_z" type="revolute">
    <origin xyz="0.05918 0.02225 0.0051" rpy="0 0 0"/>
    <parent link="l_palm"/>
    <child link="l_auri_finger_joint"/>
    <axis xyz="0 0 1"/>
    <mimic joint="l_fingers_z" multiplier="-1.5"/>
    <limit effort="100" velocity="1.0" lower="-0.4" upper="0.2" />
  </joint>

  <link name="l_auri1">
    <visual>
      <origin xyz="0 0 0" rpy="0 0 0"/>
      <geometry>
        <mesh filename="package://cs2r_desc/stl/Auriculaire1.STL"
              scale="0.001 0.001 0.001"
        />
      </geometry>
      <material name="white"/>
    </visual>
  </link>

  <joint name="l_auri" type="revolute">
    <origin xyz="0.0115 0 -0.0005" rpy="0 0 0"/>
    <parent link="l_auri_finger_joint"/>
    <child link="l_auri1"/>
    <axis xyz="0 1 0"/>
    <limit effort="100" velocity="1.0" lower="0.0" upper="1.5" />
  </joint>

  <link name="l_auri2">
    <visual>
      <origin xyz="0 0 0" rpy="0 0 0"/>
      <geometry>
        <mesh filename="package://cs2r_desc/stl/Auriculaire2.STL"
              scale="0.001 0.001 0.001"
        />
      </geometry>
      <material name="white"/>
    </visual>
  </link>

  <joint name="l_auri1_2" type="revolute">
    <origin xyz="0.019 0 0" rpy="0 0 0"/>
    <parent link="l_auri1"/>
    <child link="l_auri2"/>
    <axis xyz="0 1 0"/>
    <mimic joint="l_auri" multiplier="1"/>
    <limit effort="100" velocity="1.0" lower="0.0" upper="1.5" />
  </joint>

  <link name="l_auri3">
    <visual>
      <origin xyz="0 0 0" rpy="0 0 0"/>
      <geometry>
        <mesh filename="package://cs2r_desc/stl/Auriculaire3.STL"
              scale="0.001 0.001 0.001"
        />
      </geometry>
      <material name="white"/>
    </visual>
  </link>

  <joint name="l_auri2_3" type="revolute">
    <origin xyz="0.0125 0 0" rpy="0 0 0"/>
    <parent link="l_auri2"/>
    <child link="l_auri3"/>
    <axis xyz="0 1 0"/>
    <mimic joint="l_auri" multiplier="1"/>
    <limit effort="100" velocity="1.0" lower="0.0" upper="1.5" />
  </joint>

  <!--*********-->

  <!-- ***************************************************************************-->

  <!-- RIGHT ARM *****************************************************************-->

  <link name="r_shoulder">
    <visual>
      <origin xyz="0 0 0" rpy="0 0 0"/>
      <geometry>
        <mesh filename="package://cs2r_desc/stl/shoulder.STL"
              scale="0.001 0.001 0.001"
        />
      </geometry>
      <material name="white"/>
    </visual>
  </link>

  <joint name="r_shoulder_y" type="revolute">
    <origin xyz="0.001 -0.14819 0.1286" rpy="0 0 -1.57"/>
    <parent link="chest"/>
    <child link="r_shoulder"/>
    <axis xyz="1 0 0"/>
    <limit effort="100" velocity="1.0" lower="-1.0" upper="2.7" />
  </joint>

  <link name="r_upper_arm_up">
    <visual>
      <origin xyz="-0.0258 0.02385 -0.0416" rpy="1.57 0 0"/>
      <geometry>
        <mesh filename="package://cs2r_desc/stl/r_upper_arm_up.STL"
              scale="0.001 0.001 0.001"
        />
      </geometry>
      <material name="white"/>
    </visual>
  </link>

  <joint name="r_shoulder_x" type="revolute">
    <origin xyz="0.035 0 0" rpy="0 0 3.14"/>
    <parent link="r_shoulder"/>
    <child link="r_upper_arm_up"/>
    <axis xyz="0 1 0"/>
    <limit effort="100" velocity="1.0" lower="0" upper="1.7"/>
  </joint>

  <link name="r_upper_arm">
    <visual>
      <origin xyz="0 0 0" rpy="0 0 0"/>
      <geometry>
        <mesh filename="package://cs2r_desc/stl/upper_arm.STL"
              scale="0.001 0.001 0.001"
        />
      </geometry>
      <material name="white"/>
    </visual>
  </link>

  <joint name="r_shoulder_z" type="revolute">
    <origin xyz="0 0.01 -0.0416" rpy="0 0 -1.57"/>
    <parent link="r_upper_arm_up"/>
    <child link="r_upper_arm"/>
    <axis xyz="0 0 -1"/>
    <limit effort="100" velocity="1.0" lower="-1.57" upper="1.57" />
  </joint>

  <link name="r_elpow">
    <visual>
      <origin xyz="0 0 0" rpy="0 0 0"/>
      <geometry>
        <mesh filename="package://cs2r_desc/stl/elpow.STL"
              scale="0.001 0.001 0.001"
        />
      </geometry>
      <material name="black"/>
    </visual>
  </link>

  <joint name="r_elpow_y" type="revolute">
    <origin xyz="0.01 -0.001 -0.1557" rpy="0 0 0"/>
    <parent link="r_upper_arm"/>
    <child link="r_elpow"/>
    <axis xyz="0 -1 0"/>
    <limit effort="100" velocity="1.0" lower="0.35" upper="2.5" />
  </joint>

  <link name="r_forearm">
    <visual>
      <origin xyz="0 0 0" rpy="0 0 0"/>
      <geometry>
        <mesh filename="package://cs2r_desc/stl/r_forearm.STL"
              scale="0.001 0.001 0.001"
        />
      </geometry>
      <material name="white"/>
    </visual>
  </link>

  <joint name="r_elpow_x" type="revolute">
    <origin xyz="-0.02078 0.0 -0.03755" rpy="0 1.57 0"/>
    <parent link="r_elpow"/>
    <child link="r_forearm"/>
    <axis xyz="1 0 0"/>
    <limit effort="100" velocity="1.0" lower="0.0" upper="3.14" />
  </joint>

  <link name="r_wrist">
    <visual>
      <origin xyz="0 0 0" rpy="0 0 0"/>
      <geometry>
        <mesh filename="package://cs2r_desc/stl/wrist.STL"
              scale="0.001 0.001 0.001"
        />
      </geometry>
      <material name="white"/>
    </visual>
  </link>

  <joint name="r_wrist_y" type="revolute">
    <origin xyz="0.17325 0.0055 0" rpy="0 0 0"/>
    <parent link="r_forearm"/>
    <child link="r_wrist"/>
    <axis xyz="0 1 0"/>
    <limit effort="100" velocity="1.0" lower="-1.0" upper="1.0" />
  </joint>

  <!--right_hand-->

  <link name="r_palm">
    <visual>
      <origin xyz="0 0 0" rpy="0 0 0"/>
      <geometry>
        <mesh filename="package://cs2r_desc/stl/r_palm.STL"
              scale="0.001 0.001 0.001"
        />
      </geometry>
      <material name="white"/>
    </visual>
  </link>

  <joint name="r_wrist_z" type="revolute">
    <origin xyz="0 0 0" rpy="0 0 0"/>
    <parent link="r_wrist"/>
    <child link="r_palm"/>
    <axis xyz="0 0 1"/>
    <limit effort="100" velocity="1.0" lower="-0.65" upper="0.65" />
  </joint>

  <link name="r_thumb_joint">
    <visual>
      <origin xyz="0 0 0" rpy="0 0 0"/>
      <geometry>
        <mesh filename="package://cs2r_desc/stl/r_thumb_joint.STL"
              scale="0.001 0.001 0.001"
        />
      </geometry>
      <material name="white"/>
    </visual>
  </link>

  <joint name="r_thumb_joint_x" type="revolute">
    <origin xyz="0.0417 0.0291 -0.0057" rpy="0 0 0"/>
    <parent link="r_palm"/>
    <child link="r_thumb_joint"/>
    <axis xyz="-1 0 0"/>
    <limit effort="100" velocity="1.0" lower="0.1" upper="2" />
  </joint>

  <link name="r_thumb1">
    <visual>
      <origin xyz="0 0 0" rpy="0 0 0"/>
      <geometry>
        <mesh filename="package://cs2r_desc/stl/Thumb1.STL"
              scale="0.001 0.001 0.001"
        />
      </geometry>
      <material name="white"/>
    </visual>
  </link>

  <joint name="r_thumb" type="revolute">
    <origin xyz="0.0068 0.019 0" rpy="-0.3 0.0 1.06"/>
    <parent link="r_thumb_joint"/>
    <child link="r_thumb1"/>
    <axis xyz="0 1 0"/>
    <limit effort="100" velocity="1.0" lower="0" upper="1.4" />
  </joint>

  <link name="r_thumb2">
    <visual>
      <origin xyz="0 0 0" rpy="0 0 0"/>
      <geometry>
        <mesh filename="package://cs2r_desc/stl/Thumb2.STL"
              scale="0.001 0.001 0.001"
        />
      </geometry>
      <material name="white"/>
    </visual>
  </link>

  <joint name="r_thumb1_2" type="revolute">
    <origin xyz="0.021 0 0" rpy="0 0 0"/>
    <parent link="r_thumb1"/>
    <child link="r_thumb2"/>
    <axis xyz="0 1 0"/>
    <mimic joint="r_thumb" multiplier="1"/>
    <limit effort="100" velocity="1.0" lower="0" upper="1.4" />
  </joint>

  <link name="r_index_finger_joint">
    <visual>
      <origin xyz="0 0 0" rpy="0 0 0"/>
      <geometry>
        <mesh filename="package://cs2r_desc/stl/finger_joint.STL"
              scale="0.001 0.001 0.001"
        />
      </geometry>
      <material name="white"/>
    </visual>
  </link>

  <joint name="r_fingers_z" type="revolute">
    <origin xyz="0.06512 0.0225 0.0051" rpy="0 0 0"/>
    <parent link="r_palm"/>
    <child link="r_index_finger_joint"/>
    <axis xyz="0 0 -1"/>
    <limit effort="100" velocity="1.0" lower="-0.25" upper="0.15" />
  </joint>

  <link name="r_index1">
    <visual>
      <origin xyz="0 0 0" rpy="0 0 0"/>
      <geometry>
        <mesh filename="package://cs2r_desc/stl/Index1.STL"
              scale="0.001 0.001 0.001"
        />
      </geometry>
      <material name="white"/>
    </visual>
  </link>

  <joint name="r_index" type="revolute">
    <origin xyz="0.0115 0 -0.0005" rpy="0 0 0"/>
    <parent link="r_index_finger_joint"/>
    <child link="r_index1"/>
    <axis xyz="0 1 0"/>
    <limit effort="100" velocity="1.0" lower="0.0" upper="1.5" />
  </joint>

  <link name="r_index2">
    <visual>
      <origin xyz="0 0 0" rpy="0 0 0"/>
      <geometry>
        <mesh filename="package://cs2r_desc/stl/Index2.STL"
              scale="0.001 0.001 0.001"
        />
      </geometry>
      <material name="white"/>
    </visual>
  </link>

  <joint name="r_index1_2" type="revolute">
    <origin xyz="0.022 0 0" rpy="0 0 0"/>
    <parent link="r_index1"/>
    <child link="r_index2"/>
    <axis xyz="0 1 0"/>
    <mimic joint="r_index" multiplier="1"/>
    <limit effort="100" velocity="1.0" lower="0.0" upper="1.5" />
  </joint>

  <link name="r_index3">
    <visual>
      <origin xyz="0 0 0" rpy="0 0 0"/>
      <geometry>
        <mesh filename="package://cs2r_desc/stl/Index3.STL"
              scale="0.001 0.001 0.001"
        />
      </geometry>
      <material name="white"/>
    </visual>
  </link>

  <joint name="r_index2_3" type="revolute">
    <origin xyz="0.0146 0 0" rpy="0 0 0"/>
    <parent link="r_index2"/>
    <child link="r_index3"/>
    <axis xyz="0 1 0"/>
    <mimic joint="r_index" multiplier="1"/>
    <limit effort="100" velocity="1.0" lower="0.0" upper="1.5" />
  </joint>

  <link name="r_middle_finger_joint">
    <visual>
      <origin xyz="0 0 0" rpy="0 0 0"/>
      <geometry>
        <mesh filename="package://cs2r_desc/stl/finger_joint.STL"
              scale="0.001 0.001 0.001"
        />
      </geometry>
      <material name="white"/>
    </visual>
  </link>

  <joint name="r_midlle_z" type="fixed">
    <origin xyz="0.0665 0.00733 0.0051" rpy="0 0 0"/>
    <parent link="r_palm"/>
    <child link="r_middle_finger_joint"/>
  </joint>

  <link name="r_middle1">
    <visual>
      <origin xyz="0 0 0" rpy="0 0 0"/>
      <geometry>
        <mesh filename="package://cs2r_desc/stl/Majeure1.STL"
              scale="0.001 0.001 0.001"
        />
      </geometry>
      <material name="white"/>
    </visual>
  </link>

  <joint name="r_middle" type="revolute">
    <origin xyz="0.0115 0 -0.0005" rpy="0 0 0"/>
    <parent link="r_middle_finger_joint"/>
    <child link="r_middle1"/>
    <axis xyz="0 1 0"/>
    <limit effort="100" velocity="1.0" lower="0.0" upper="1.5" />
  </joint>

  <link name="r_middle2">
    <visual>
      <origin xyz="0 0 0" rpy="0 0 0"/>
      <geometry>
        <mesh filename="package://cs2r_desc/stl/Majeure2.STL"
              scale="0.001 0.001 0.001"
        />
      </geometry>
      <material name="white"/>
    </visual>
  </link>

  <joint name="r_middle1_2" type="revolute">
    <origin xyz="0.023 0 0" rpy="0 0 0"/>
    <parent link="r_middle1"/>
    <child link="r_middle2"/>
    <axis xyz="0 1 0"/>
    <mimic joint="r_middle" multiplier="1"/>
    <limit effort="100" velocity="1.0" lower="0.0" upper="1.5" />
  </joint>

  <link name="r_middle3">
    <visual>
      <origin xyz="0 0 0" rpy="0 0 0"/>
      <geometry>
        <mesh filename="package://cs2r_desc/stl/Majeure3.STL"
              scale="0.001 0.001 0.001"
        />
      </geometry>
      <material name="white"/>
    </visual>
  </link>

  <joint name="r_middle2_3" type="revolute">
    <origin xyz="0.0155 0 0" rpy="0 0 0"/>
    <parent link="r_middle2"/>
    <child link="r_middle3"/>
    <axis xyz="0 1 0"/>
    <mimic joint="r_middle" multiplier="1"/>
    <limit effort="100" velocity="1.0" lower="0.0" upper="1.5" />
  </joint>

  <link name="r_ring_finger_joint">
    <visual>
      <origin xyz="0 0 0" rpy="0 0 0"/>
      <geometry>
        <mesh filename="package://cs2r_desc/stl/finger_joint.STL"
              scale="0.001 0.001 0.001"
        />
      </geometry>
      <material name="white"/>
    </visual>
  </link>

  <joint name="r_ring_z" type="revolute">
    <origin xyz="0.064 -0.00747 0.0051" rpy="0 0 0"/>
    <parent link="r_palm"/>
    <child link="r_ring_finger_joint"/>
    <axis xyz="0 0 -1"/>
    <mimic joint="r_fingers_z" multiplier="-1"/>
    <limit effort="100" velocity="1.0" lower="-0.4" upper="0.2" />
  </joint>

  <link name="r_ring1">
    <visual>
      <origin xyz="0 0 0" rpy="0 0 0"/>
      <geometry>
        <mesh filename="package://cs2r_desc/stl/RingFinger1.STL"
              scale="0.001 0.001 0.001"
        />
      </geometry>
      <material name="white"/>
    </visual>
  </link>

  <joint name="r_ring" type="revolute">
    <origin xyz="0.0115 0 -0.0005" rpy="0 0 0"/>
    <parent link="r_ring_finger_joint"/>
    <child link="r_ring1"/>
    <axis xyz="0 1 0"/>
    <limit effort="100" velocity="1.0" lower="0.0" upper="1.5" />
  </joint>

  <link name="r_ring2">
    <visual>
      <origin xyz="0 0 0" rpy="0 0 0"/>
      <geometry>
        <mesh filename="package://cs2r_desc/stl/RingFinger2.STL"
              scale="0.001 0.001 0.001"
        />
      </geometry>
      <material name="white"/>
    </visual>
  </link>

  <joint name="r_ring1_2" type="revolute">
    <origin xyz="0.021 0 0" rpy="0 0 0"/>
    <parent link="r_ring1"/>
    <child link="r_ring2"/>
    <axis xyz="0 1 0"/>
    <mimic joint="r_ring" multiplier="1"/>
    <limit effort="100" velocity="1.0" lower="0.0" upper="1.5" />
  </joint>

  <link name="r_ring3">
    <visual>
      <origin xyz="0 0 0" rpy="0 0 0"/>
      <geometry>
        <mesh filename="package://cs2r_desc/stl/RingFinger3.STL"
              scale="0.001 0.001 0.001"
        />
      </geometry>
      <material name="white"/>
    </visual>
  </link>

  <joint name="r_ring2_3" type="revolute">
    <origin xyz="0.014 0 0" rpy="0 0 0"/>
    <parent link="r_ring2"/>
    <child link="r_ring3"/>
    <axis xyz="0 1 0"/>
    <mimic joint="r_ring" multiplier="1"/>
    <limit effort="100" velocity="1.0" lower="0.0" upper="1.5" />
  </joint>

  <link name="r_auri_finger_joint">
    <visual>
      <origin xyz="0 0 0" rpy="0 0 0"/>
      <geometry>
        <mesh filename="package://cs2r_desc/stl/finger_joint.STL"
              scale="0.001 0.001 0.001"
        />
      </geometry>
      <material name="white"/>
    </visual>
  </link>

  <joint name="r_auri_z" type="revolute">
    <origin xyz="0.05918 -0.02225 0.0051" rpy="0 0 0"/>
    <parent link="r_palm"/>
    <child link="r_auri_finger_joint"/>
    <axis xyz="0 0 -1"/>
    <mimic joint="r_fingers_z" multiplier="-1.5"/>
    <limit effort="100" velocity="1.0" lower="-0.4" upper="0.2" />
  </joint>


  <link name="r_auri1">
    <visual>
      <origin xyz="0 0 0" rpy="0 0 0"/>
      <geometry>
        <mesh filename="package://cs2r_desc/stl/Auriculaire1.STL"
              scale="0.001 0.001 0.001"
        />
      </geometry>
      <material name="white"/>
    </visual>
  </link>

  <joint name="r_auri" type="revolute">
    <origin xyz="0.0115 0 -0.0005" rpy="0 0 0"/>
    <parent link="r_auri_finger_joint"/>
    <child link="r_auri1"/>
    <axis xyz="0 1 0"/>
    <limit effort="100" velocity="1.0" lower="0.0" upper="1.5" />
  </joint>

  <link name="r_auri2">
    <visual>
      <origin xyz="0 0 0" rpy="0 0 0"/>
      <geometry>
        <mesh filename="package://cs2r_desc/stl/Auriculaire2.STL"
              scale="0.001 0.001 0.001"
        />
      </geometry>
      <material name="white"/>
    </visual>
  </link>

  <joint name="r_auri1_2" type="revolute">
    <origin xyz="0.019 0 0" rpy="0 0 0"/>
    <parent link="r_auri1"/>
    <child link="r_auri2"/>
    <axis xyz="0 1 0"/>
    <mimic joint="r_auri" multiplier="1"/>
    <limit effort="100" velocity="1.0" lower="0.0" upper="1.5" />
  </joint>

  <link name="r_auri3">
    <visual>
      <origin xyz="0 0 0" rpy="0 0 0"/>
      <geometry>
        <mesh filename="package://cs2r_desc/stl/Auriculaire3.STL"
              scale="0.001 0.001 0.001"
        />
      </geometry>
      <material name="white"/>
    </visual>
  </link>

  <joint name="r_auri2_3" type="revolute">
    <origin xyz="0.0125 0 0" rpy="0 0 0"/>
    <parent link="r_auri2"/>
    <child link="r_auri3"/>
    <axis xyz="0 1 0"/>
    <mimic joint="r_auri" multiplier="1"/>
    <limit effort="100" velocity="1.0" lower="0.0" upper="1.5" />
  </joint>

  <!--*********-->
  <!-- ***************************************************************************-->

</robot>

